2025-10-18 21:43:20,072 - INFO - 配置验证通过
2025-10-18 21:43:20,072 - INFO - 开始执行刷步数任务
多账号执行间隔：10.0
[2025-10-19 05:43:20]
[1/7]账号：257****.com
第1次尝试失败，2次重试机会: HTTPSConnectionPool(host='api-mifit-cn3.zepp.com', port=443): Max retries exceeded with url: /huami.health.getUserInfo.json?r=00b7912b-790a-4552-81b1-3742f9dd1e76&userid=1188760659&appid=428135909242707968&channel=Normal&country=CN&cv=50818_6.14.0&device=android_31&device_type=android_phone&lang=zh_CN&timezone=Asia%2FShanghai&v=2.0 (Caused by ConnectTimeoutError(<urllib3.connection.HTTPSConnection object at 0x7f11c27df340>, 'Connection to api-mifit-cn3.zepp.com timed out. (connect timeout=None)'))
第2次尝试失败，1次重试机会: HTTPSConnectionPool(host='api-mifit-cn3.zepp.com', port=443): Max retries exceeded with url: /huami.health.getUserInfo.json?r=00b7912b-790a-4552-81b1-3742f9dd1e76&userid=1188760659&appid=428135909242707968&channel=Normal&country=CN&cv=50818_6.14.0&device=android_31&device_type=android_phone&lang=zh_CN&timezone=Asia%2FShanghai&v=2.0 (Caused by ConnectTimeoutError(<urllib3.connection.HTTPSConnection object at 0x7f11c27de9b0>, 'Connection to api-mifit-cn3.zepp.com timed out. (connect timeout=None)'))
执行异常（已重试3次）:Traceback (most recent call last):
  File "/opt/hostedtoolcache/Python/3.10.19/x64/lib/python3.10/site-packages/urllib3/connection.py", line 198, in _new_conn
    sock = connection.create_connection(
  File "/opt/hostedtoolcache/Python/3.10.19/x64/lib/python3.10/site-packages/urllib3/util/connection.py", line 85, in create_connection
    raise err
  File "/opt/hostedtoolcache/Python/3.10.19/x64/lib/python3.10/site-packages/urllib3/util/connection.py", line 73, in create_connection
    sock.connect(sa)
TimeoutError: [Errno 110] Connection timed out

The above exception was the direct cause of the following exception:

Traceback (most recent call last):
  File "/opt/hostedtoolcache/Python/3.10.19/x64/lib/python3.10/site-packages/urllib3/connectionpool.py", line 787, in urlopen
    response = self._make_request(
  File "/opt/hostedtoolcache/Python/3.10.19/x64/lib/python3.10/site-packages/urllib3/connectionpool.py", line 488, in _make_request
    raise new_e
  File "/opt/hostedtoolcache/Python/3.10.19/x64/lib/python3.10/site-packages/urllib3/connectionpool.py", line 464, in _make_request
    self._validate_conn(conn)
  File "/opt/hostedtoolcache/Python/3.10.19/x64/lib/python3.10/site-packages/urllib3/connectionpool.py", line 1093, in _validate_conn
    conn.connect()
  File "/opt/hostedtoolcache/Python/3.10.19/x64/lib/python3.10/site-packages/urllib3/connection.py", line 753, in connect
    self.sock = sock = self._new_conn()
  File "/opt/hostedtoolcache/Python/3.10.19/x64/lib/python3.10/site-packages/urllib3/connection.py", line 207, in _new_conn
    raise ConnectTimeoutError(
urllib3.exceptions.ConnectTimeoutError: (<urllib3.connection.HTTPSConnection object at 0x7f11c27de110>, 'Connection to api-mifit-cn3.zepp.com timed out. (connect timeout=None)')

The above exception was the direct cause of the following exception:

Traceback (most recent call last):
  File "/opt/hostedtoolcache/Python/3.10.19/x64/lib/python3.10/site-packages/requests/adapters.py", line 644, in send
    resp = conn.urlopen(
  File "/opt/hostedtoolcache/Python/3.10.19/x64/lib/python3.10/site-packages/urllib3/connectionpool.py", line 841, in urlopen
    retries = retries.increment(
  File "/opt/hostedtoolcache/Python/3.10.19/x64/lib/python3.10/site-packages/urllib3/util/retry.py", line 519, in increment
    raise MaxRetryError(_pool, url, reason) from reason  # type: ignore[arg-type]
urllib3.exceptions.MaxRetryError: HTTPSConnectionPool(host='api-mifit-cn3.zepp.com', port=443): Max retries exceeded with url: /huami.health.getUserInfo.json?r=00b7912b-790a-4552-81b1-3742f9dd1e76&userid=1188760659&appid=428135909242707968&channel=Normal&country=CN&cv=50818_6.14.0&device=android_31&device_type=android_phone&lang=zh_CN&timezone=Asia%2FShanghai&v=2.0 (Caused by ConnectTimeoutError(<urllib3.connection.HTTPSConnection object at 0x7f11c27de110>, 'Connection to api-mifit-cn3.zepp.com timed out. (connect timeout=None)'))

During handling of the above exception, another exception occurred:

Traceback (most recent call last):
  File "/home/runner/work/mimotion/mimotion/main.py", line 302, in run_single_account
    exec_msg, success = runner.login_and_post_step(min_step, max_step)
  File "/home/runner/work/mimotion/mimotion/main.py", line 260, in login_and_post_step
    app_token = self.login()
  File "/home/runner/work/mimotion/mimotion/main.py", line 202, in login
    ok,msg = zeppHelper.check_app_token(app_token)
  File "/home/runner/work/mimotion/mimotion/util/zepp_helper.py", line 198, in check_app_token
    response = requests.get(url, params=params, headers=headers)
  File "/opt/hostedtoolcache/Python/3.10.19/x64/lib/python3.10/site-packages/requests/api.py", line 73, in get
    return request("get", url, params=params, **kwargs)
  File "/opt/hostedtoolcache/Python/3.10.19/x64/lib/python3.10/site-packages/requests/api.py", line 59, in request
    return session.request(method=method, url=url, **kwargs)
  File "/opt/hostedtoolcache/Python/3.10.19/x64/lib/python3.10/site-packages/requests/sessions.py", line 589, in request
    resp = self.send(prep, **send_kwargs)
  File "/opt/hostedtoolcache/Python/3.10.19/x64/lib/python3.10/site-packages/requests/sessions.py", line 703, in send
    r = adapter.send(request, **kwargs)
  File "/opt/hostedtoolcache/Python/3.10.19/x64/lib/python3.10/site-packages/requests/adapters.py", line 665, in send
    raise ConnectTimeout(e, request=request)
requests.exceptions.ConnectTimeout: HTTPSConnectionPool(host='api-mifit-cn3.zepp.com', port=443): Max retries exceeded with url: /huami.health.getUserInfo.json?r=00b7912b-790a-4552-81b1-3742f9dd1e76&userid=1188760659&appid=428135909242707968&channel=Normal&country=CN&cv=50818_6.14.0&device=android_31&device_type=android_phone&lang=zh_CN&timezone=Asia%2FShanghai&v=2.0 (Caused by ConnectTimeoutError(<urllib3.connection.HTTPSConnection object at 0x7f11c27de110>, 'Connection to api-mifit-cn3.zepp.com timed out. (connect timeout=None)'))


[2025-10-19 05:50:16]
[2/7]账号：114****.com
第1次尝试失败，2次重试机会: HTTPSConnectionPool(host='api-mifit-cn3.zepp.com', port=443): Max retries exceeded with url: /huami.health.getUserInfo.json?r=00b7912b-790a-4552-81b1-3742f9dd1e76&userid=1188760659&appid=428135909242707968&channel=Normal&country=CN&cv=50818_6.14.0&device=android_31&device_type=android_phone&lang=zh_CN&timezone=Asia%2FShanghai&v=2.0 (Caused by ConnectTimeoutError(<urllib3.connection.HTTPSConnection object at 0x7f11c27ded10>, 'Connection to api-mifit-cn3.zepp.com timed out. (connect timeout=None)'))
第2次尝试失败，1次重试机会: HTTPSConnectionPool(host='api-mifit-cn3.zepp.com', port=443): Max retries exceeded with url: /huami.health.getUserInfo.json?r=00b7912b-790a-4552-81b1-3742f9dd1e76&userid=1188760659&appid=428135909242707968&channel=Normal&country=CN&cv=50818_6.14.0&device=android_31&device_type=android_phone&lang=zh_CN&timezone=Asia%2FShanghai&v=2.0 (Caused by ConnectTimeoutError(<urllib3.connection.HTTPSConnection object at 0x7f11c27ddfc0>, 'Connection to api-mifit-cn3.zepp.com timed out. (connect timeout=None)'))
执行异常（已重试3次）:Traceback (most recent call last):
  File "/opt/hostedtoolcache/Python/3.10.19/x64/lib/python3.10/site-packages/urllib3/connection.py", line 198, in _new_conn
    sock = connection.create_connection(
  File "/opt/hostedtoolcache/Python/3.10.19/x64/lib/python3.10/site-packages/urllib3/util/connection.py", line 85, in create_connection
    raise err
  File "/opt/hostedtoolcache/Python/3.10.19/x64/lib/python3.10/site-packages/urllib3/util/connection.py", line 73, in create_connection
    sock.connect(sa)
TimeoutError: [Errno 110] Connection timed out

The above exception was the direct cause of the following exception:

Traceback (most recent call last):
  File "/opt/hostedtoolcache/Python/3.10.19/x64/lib/python3.10/site-packages/urllib3/connectionpool.py", line 787, in urlopen
    response = self._make_request(
  File "/opt/hostedtoolcache/Python/3.10.19/x64/lib/python3.10/site-packages/urllib3/connectionpool.py", line 488, in _make_request
    raise new_e
  File "/opt/hostedtoolcache/Python/3.10.19/x64/lib/python3.10/site-packages/urllib3/connectionpool.py", line 464, in _make_request
    self._validate_conn(conn)
  File "/opt/hostedtoolcache/Python/3.10.19/x64/lib/python3.10/site-packages/urllib3/connectionpool.py", line 1093, in _validate_conn
    conn.connect()
  File "/opt/hostedtoolcache/Python/3.10.19/x64/lib/python3.10/site-packages/urllib3/connection.py", line 753, in connect
    self.sock = sock = self._new_conn()
  File "/opt/hostedtoolcache/Python/3.10.19/x64/lib/python3.10/site-packages/urllib3/connection.py", line 207, in _new_conn
    raise ConnectTimeoutError(
urllib3.exceptions.ConnectTimeoutError: (<urllib3.connection.HTTPSConnection object at 0x7f11c27dd750>, 'Connection to api-mifit-cn3.zepp.com timed out. (connect timeout=None)')

The above exception was the direct cause of the following exception:

Traceback (most recent call last):
  File "/opt/hostedtoolcache/Python/3.10.19/x64/lib/python3.10/site-packages/requests/adapters.py", line 644, in send
    resp = conn.urlopen(
  File "/opt/hostedtoolcache/Python/3.10.19/x64/lib/python3.10/site-packages/urllib3/connectionpool.py", line 841, in urlopen
    retries = retries.increment(
  File "/opt/hostedtoolcache/Python/3.10.19/x64/lib/python3.10/site-packages/urllib3/util/retry.py", line 519, in increment
    raise MaxRetryError(_pool, url, reason) from reason  # type: ignore[arg-type]
urllib3.exceptions.MaxRetryError: HTTPSConnectionPool(host='api-mifit-cn3.zepp.com', port=443): Max retries exceeded with url: /huami.health.getUserInfo.json?r=00b7912b-790a-4552-81b1-3742f9dd1e76&userid=1188760659&appid=428135909242707968&channel=Normal&country=CN&cv=50818_6.14.0&device=android_31&device_type=android_phone&lang=zh_CN&timezone=Asia%2FShanghai&v=2.0 (Caused by ConnectTimeoutError(<urllib3.connection.HTTPSConnection object at 0x7f11c27dd750>, 'Connection to api-mifit-cn3.zepp.com timed out. (connect timeout=None)'))

During handling of the above exception, another exception occurred:

Traceback (most recent call last):
  File "/home/runner/work/mimotion/mimotion/main.py", line 302, in run_single_account
    exec_msg, success = runner.login_and_post_step(min_step, max_step)
  File "/home/runner/work/mimotion/mimotion/main.py", line 260, in login_and_post_step
    app_token = self.login()
  File "/home/runner/work/mimotion/mimotion/main.py", line 202, in login
    ok,msg = zeppHelper.check_app_token(app_token)
  File "/home/runner/work/mimotion/mimotion/util/zepp_helper.py", line 198, in check_app_token
    response = requests.get(url, params=params, headers=headers)
  File "/opt/hostedtoolcache/Python/3.10.19/x64/lib/python3.10/site-packages/requests/api.py", line 73, in get
    return request("get", url, params=params, **kwargs)
  File "/opt/hostedtoolcache/Python/3.10.19/x64/lib/python3.10/site-packages/requests/api.py", line 59, in request
    return session.request(method=method, url=url, **kwargs)
  File "/opt/hostedtoolcache/Python/3.10.19/x64/lib/python3.10/site-packages/requests/sessions.py", line 589, in request
    resp = self.send(prep, **send_kwargs)
  File "/opt/hostedtoolcache/Python/3.10.19/x64/lib/python3.10/site-packages/requests/sessions.py", line 703, in send
    r = adapter.send(request, **kwargs)
  File "/opt/hostedtoolcache/Python/3.10.19/x64/lib/python3.10/site-packages/requests/adapters.py", line 665, in send
    raise ConnectTimeout(e, request=request)
requests.exceptions.ConnectTimeout: HTTPSConnectionPool(host='api-mifit-cn3.zepp.com', port=443): Max retries exceeded with url: /huami.health.getUserInfo.json?r=00b7912b-790a-4552-81b1-3742f9dd1e76&userid=1188760659&appid=428135909242707968&channel=Normal&country=CN&cv=50818_6.14.0&device=android_31&device_type=android_phone&lang=zh_CN&timezone=Asia%2FShanghai&v=2.0 (Caused by ConnectTimeoutError(<urllib3.connection.HTTPSConnection object at 0x7f11c27dd750>, 'Connection to api-mifit-cn3.zepp.com timed out. (connect timeout=None)'))


[2025-10-19 05:57:10]
[3/7]账号：255****.com
第1次尝试失败，2次重试机会: HTTPSConnectionPool(host='api-mifit-cn3.zepp.com', port=443): Max retries exceeded with url: /huami.health.getUserInfo.json?r=00b7912b-790a-4552-81b1-3742f9dd1e76&userid=1188760659&appid=428135909242707968&channel=Normal&country=CN&cv=50818_6.14.0&device=android_31&device_type=android_phone&lang=zh_CN&timezone=Asia%2FShanghai&v=2.0 (Caused by ConnectTimeoutError(<urllib3.connection.HTTPSConnection object at 0x7f11c27dcee0>, 'Connection to api-mifit-cn3.zepp.com timed out. (connect timeout=None)'))
第2次尝试失败，1次重试机会: HTTPSConnectionPool(host='api-mifit-cn3.zepp.com', port=443): Max retries exceeded with url: /huami.health.getUserInfo.json?r=00b7912b-790a-4552-81b1-3742f9dd1e76&userid=1188760659&appid=428135909242707968&channel=Normal&country=CN&cv=50818_6.14.0&device=android_31&device_type=android_phone&lang=zh_CN&timezone=Asia%2FShanghai&v=2.0 (Caused by ConnectTimeoutError(<urllib3.connection.HTTPSConnection object at 0x7f11c39982b0>, 'Connection to api-mifit-cn3.zepp.com timed out. (connect timeout=None)'))
执行异常（已重试3次）:Traceback (most recent call last):
  File "/opt/hostedtoolcache/Python/3.10.19/x64/lib/python3.10/site-packages/urllib3/connection.py", line 198, in _new_conn
    sock = connection.create_connection(
  File "/opt/hostedtoolcache/Python/3.10.19/x64/lib/python3.10/site-packages/urllib3/util/connection.py", line 85, in create_connection
    raise err
  File "/opt/hostedtoolcache/Python/3.10.19/x64/lib/python3.10/site-packages/urllib3/util/connection.py", line 73, in create_connection
    sock.connect(sa)
TimeoutError: [Errno 110] Connection timed out

The above exception was the direct cause of the following exception:

Traceback (most recent call last):
  File "/opt/hostedtoolcache/Python/3.10.19/x64/lib/python3.10/site-packages/urllib3/connectionpool.py", line 787, in urlopen
    response = self._make_request(
  File "/opt/hostedtoolcache/Python/3.10.19/x64/lib/python3.10/site-packages/urllib3/connectionpool.py", line 488, in _make_request
    raise new_e
  File "/opt/hostedtoolcache/Python/3.10.19/x64/lib/python3.10/site-packages/urllib3/connectionpool.py", line 464, in _make_request
    self._validate_conn(conn)
  File "/opt/hostedtoolcache/Python/3.10.19/x64/lib/python3.10/site-packages/urllib3/connectionpool.py", line 1093, in _validate_conn
    conn.connect()
  File "/opt/hostedtoolcache/Python/3.10.19/x64/lib/python3.10/site-packages/urllib3/connection.py", line 753, in connect
    self.sock = sock = self._new_conn()
  File "/opt/hostedtoolcache/Python/3.10.19/x64/lib/python3.10/site-packages/urllib3/connection.py", line 207, in _new_conn
    raise ConnectTimeoutError(
urllib3.exceptions.ConnectTimeoutError: (<urllib3.connection.HTTPSConnection object at 0x7f11c27dd390>, 'Connection to api-mifit-cn3.zepp.com timed out. (connect timeout=None)')

The above exception was the direct cause of the following exception:

Traceback (most recent call last):
  File "/opt/hostedtoolcache/Python/3.10.19/x64/lib/python3.10/site-packages/requests/adapters.py", line 644, in send
    resp = conn.urlopen(
  File "/opt/hostedtoolcache/Python/3.10.19/x64/lib/python3.10/site-packages/urllib3/connectionpool.py", line 841, in urlopen
    retries = retries.increment(
  File "/opt/hostedtoolcache/Python/3.10.19/x64/lib/python3.10/site-packages/urllib3/util/retry.py", line 519, in increment
    raise MaxRetryError(_pool, url, reason) from reason  # type: ignore[arg-type]
urllib3.exceptions.MaxRetryError: HTTPSConnectionPool(host='api-mifit-cn3.zepp.com', port=443): Max retries exceeded with url: /huami.health.getUserInfo.json?r=00b7912b-790a-4552-81b1-3742f9dd1e76&userid=1188760659&appid=428135909242707968&channel=Normal&country=CN&cv=50818_6.14.0&device=android_31&device_type=android_phone&lang=zh_CN&timezone=Asia%2FShanghai&v=2.0 (Caused by ConnectTimeoutError(<urllib3.connection.HTTPSConnection object at 0x7f11c27dd390>, 'Connection to api-mifit-cn3.zepp.com timed out. (connect timeout=None)'))

During handling of the above exception, another exception occurred:

Traceback (most recent call last):
  File "/home/runner/work/mimotion/mimotion/main.py", line 302, in run_single_account
    exec_msg, success = runner.login_and_post_step(min_step, max_step)
  File "/home/runner/work/mimotion/mimotion/main.py", line 260, in login_and_post_step
    app_token = self.login()
  File "/home/runner/work/mimotion/mimotion/main.py", line 202, in login
    ok,msg = zeppHelper.check_app_token(app_token)
  File "/home/runner/work/mimotion/mimotion/util/zepp_helper.py", line 198, in check_app_token
    response = requests.get(url, params=params, headers=headers)
  File "/opt/hostedtoolcache/Python/3.10.19/x64/lib/python3.10/site-packages/requests/api.py", line 73, in get
    return request("get", url, params=params, **kwargs)
  File "/opt/hostedtoolcache/Python/3.10.19/x64/lib/python3.10/site-packages/requests/api.py", line 59, in request
    return session.request(method=method, url=url, **kwargs)
  File "/opt/hostedtoolcache/Python/3.10.19/x64/lib/python3.10/site-packages/requests/sessions.py", line 589, in request
    resp = self.send(prep, **send_kwargs)
  File "/opt/hostedtoolcache/Python/3.10.19/x64/lib/python3.10/site-packages/requests/sessions.py", line 703, in send
    r = adapter.send(request, **kwargs)
  File "/opt/hostedtoolcache/Python/3.10.19/x64/lib/python3.10/site-packages/requests/adapters.py", line 665, in send
    raise ConnectTimeout(e, request=request)
requests.exceptions.ConnectTimeout: HTTPSConnectionPool(host='api-mifit-cn3.zepp.com', port=443): Max retries exceeded with url: /huami.health.getUserInfo.json?r=00b7912b-790a-4552-81b1-3742f9dd1e76&userid=1188760659&appid=428135909242707968&channel=Normal&country=CN&cv=50818_6.14.0&device=android_31&device_type=android_phone&lang=zh_CN&timezone=Asia%2FShanghai&v=2.0 (Caused by ConnectTimeoutError(<urllib3.connection.HTTPSConnection object at 0x7f11c27dd390>, 'Connection to api-mifit-cn3.zepp.com timed out. (connect timeout=None)'))


[2025-10-19 06:04:03]
[4/7]账号：273****.com
第1次尝试失败，2次重试机会: HTTPSConnectionPool(host='api-mifit-cn3.zepp.com', port=443): Max retries exceeded with url: /huami.health.getUserInfo.json?r=00b7912b-790a-4552-81b1-3742f9dd1e76&userid=1188760659&appid=428135909242707968&channel=Normal&country=CN&cv=50818_6.14.0&device=android_31&device_type=android_phone&lang=zh_CN&timezone=Asia%2FShanghai&v=2.0 (Caused by ConnectTimeoutError(<urllib3.connection.HTTPSConnection object at 0x7f11c27ddc00>, 'Connection to api-mifit-cn3.zepp.com timed out. (connect timeout=None)'))
第2次尝试失败，1次重试机会: HTTPSConnectionPool(host='api-mifit-cn3.zepp.com', port=443): Max retries exceeded with url: /huami.health.getUserInfo.json?r=00b7912b-790a-4552-81b1-3742f9dd1e76&userid=1188760659&appid=428135909242707968&channel=Normal&country=CN&cv=50818_6.14.0&device=android_31&device_type=android_phone&lang=zh_CN&timezone=Asia%2FShanghai&v=2.0 (Caused by ConnectTimeoutError(<urllib3.connection.HTTPSConnection object at 0x7f11c27df1f0>, 'Connection to api-mifit-cn3.zepp.com timed out. (connect timeout=None)'))
执行异常（已重试3次）:Traceback (most recent call last):
  File "/opt/hostedtoolcache/Python/3.10.19/x64/lib/python3.10/site-packages/urllib3/connection.py", line 198, in _new_conn
    sock = connection.create_connection(
  File "/opt/hostedtoolcache/Python/3.10.19/x64/lib/python3.10/site-packages/urllib3/util/connection.py", line 85, in create_connection
    raise err
  File "/opt/hostedtoolcache/Python/3.10.19/x64/lib/python3.10/site-packages/urllib3/util/connection.py", line 73, in create_connection
    sock.connect(sa)
TimeoutError: [Errno 110] Connection timed out

The above exception was the direct cause of the following exception:

Traceback (most recent call last):
  File "/opt/hostedtoolcache/Python/3.10.19/x64/lib/python3.10/site-packages/urllib3/connectionpool.py", line 787, in urlopen
    response = self._make_request(
  File "/opt/hostedtoolcache/Python/3.10.19/x64/lib/python3.10/site-packages/urllib3/connectionpool.py", line 488, in _make_request
    raise new_e
  File "/opt/hostedtoolcache/Python/3.10.19/x64/lib/python3.10/site-packages/urllib3/connectionpool.py", line 464, in _make_request
    self._validate_conn(conn)
  File "/opt/hostedtoolcache/Python/3.10.19/x64/lib/python3.10/site-packages/urllib3/connectionpool.py", line 1093, in _validate_conn
    conn.connect()
  File "/opt/hostedtoolcache/Python/3.10.19/x64/lib/python3.10/site-packages/urllib3/connection.py", line 753, in connect
    self.sock = sock = self._new_conn()
  File "/opt/hostedtoolcache/Python/3.10.19/x64/lib/python3.10/site-packages/urllib3/connection.py", line 207, in _new_conn
    raise ConnectTimeoutError(
urllib3.exceptions.ConnectTimeoutError: (<urllib3.connection.HTTPSConnection object at 0x7f11c27de560>, 'Connection to api-mifit-cn3.zepp.com timed out. (connect timeout=None)')

The above exception was the direct cause of the following exception:

Traceback (most recent call last):
  File "/opt/hostedtoolcache/Python/3.10.19/x64/lib/python3.10/site-packages/requests/adapters.py", line 644, in send
    resp = conn.urlopen(
  File "/opt/hostedtoolcache/Python/3.10.19/x64/lib/python3.10/site-packages/urllib3/connectionpool.py", line 841, in urlopen
    retries = retries.increment(
  File "/opt/hostedtoolcache/Python/3.10.19/x64/lib/python3.10/site-packages/urllib3/util/retry.py", line 519, in increment
    raise MaxRetryError(_pool, url, reason) from reason  # type: ignore[arg-type]
urllib3.exceptions.MaxRetryError: HTTPSConnectionPool(host='api-mifit-cn3.zepp.com', port=443): Max retries exceeded with url: /huami.health.getUserInfo.json?r=00b7912b-790a-4552-81b1-3742f9dd1e76&userid=1188760659&appid=428135909242707968&channel=Normal&country=CN&cv=50818_6.14.0&device=android_31&device_type=android_phone&lang=zh_CN&timezone=Asia%2FShanghai&v=2.0 (Caused by ConnectTimeoutError(<urllib3.connection.HTTPSConnection object at 0x7f11c27de560>, 'Connection to api-mifit-cn3.zepp.com timed out. (connect timeout=None)'))

During handling of the above exception, another exception occurred:

Traceback (most recent call last):
  File "/home/runner/work/mimotion/mimotion/main.py", line 302, in run_single_account
    exec_msg, success = runner.login_and_post_step(min_step, max_step)
  File "/home/runner/work/mimotion/mimotion/main.py", line 260, in login_and_post_step
    app_token = self.login()
  File "/home/runner/work/mimotion/mimotion/main.py", line 202, in login
    ok,msg = zeppHelper.check_app_token(app_token)
  File "/home/runner/work/mimotion/mimotion/util/zepp_helper.py", line 198, in check_app_token
    response = requests.get(url, params=params, headers=headers)
  File "/opt/hostedtoolcache/Python/3.10.19/x64/lib/python3.10/site-packages/requests/api.py", line 73, in get
    return request("get", url, params=params, **kwargs)
  File "/opt/hostedtoolcache/Python/3.10.19/x64/lib/python3.10/site-packages/requests/api.py", line 59, in request
    return session.request(method=method, url=url, **kwargs)
  File "/opt/hostedtoolcache/Python/3.10.19/x64/lib/python3.10/site-packages/requests/sessions.py", line 589, in request
    resp = self.send(prep, **send_kwargs)
  File "/opt/hostedtoolcache/Python/3.10.19/x64/lib/python3.10/site-packages/requests/sessions.py", line 703, in send
    r = adapter.send(request, **kwargs)
  File "/opt/hostedtoolcache/Python/3.10.19/x64/lib/python3.10/site-packages/requests/adapters.py", line 665, in send
    raise ConnectTimeout(e, request=request)
requests.exceptions.ConnectTimeout: HTTPSConnectionPool(host='api-mifit-cn3.zepp.com', port=443): Max retries exceeded with url: /huami.health.getUserInfo.json?r=00b7912b-790a-4552-81b1-3742f9dd1e76&userid=1188760659&appid=428135909242707968&channel=Normal&country=CN&cv=50818_6.14.0&device=android_31&device_type=android_phone&lang=zh_CN&timezone=Asia%2FShanghai&v=2.0 (Caused by ConnectTimeoutError(<urllib3.connection.HTTPSConnection object at 0x7f11c27de560>, 'Connection to api-mifit-cn3.zepp.com timed out. (connect timeout=None)'))


[2025-10-19 06:10:57]
[5/7]账号：328****.com
登录获取accessToken失败：获取accessToken失败 401登陆失败！

[2025-10-19 06:11:08]
[6/7]账号：671****.com
第1次尝试失败，2次重试机会: HTTPSConnectionPool(host='api-mifit-cn3.zepp.com', port=443): Max retries exceeded with url: /huami.health.getUserInfo.json?r=00b7912b-790a-4552-81b1-3742f9dd1e76&userid=1188760659&appid=428135909242707968&channel=Normal&country=CN&cv=50818_6.14.0&device=android_31&device_type=android_phone&lang=zh_CN&timezone=Asia%2FShanghai&v=2.0 (Caused by ConnectTimeoutError(<urllib3.connection.HTTPSConnection object at 0x7f11c27de0e0>, 'Connection to api-mifit-cn3.zepp.com timed out. (connect timeout=None)'))
第2次尝试失败，1次重试机会: HTTPSConnectionPool(host='api-mifit-cn3.zepp.com', port=443): Max retries exceeded with url: /huami.health.getUserInfo.json?r=00b7912b-790a-4552-81b1-3742f9dd1e76&userid=1188760659&appid=428135909242707968&channel=Normal&country=CN&cv=50818_6.14.0&device=android_31&device_type=android_phone&lang=zh_CN&timezone=Asia%2FShanghai&v=2.0 (Caused by ConnectTimeoutError(<urllib3.connection.HTTPSConnection object at 0x7f11c27deaa0>, 'Connection to api-mifit-cn3.zepp.com timed out. (connect timeout=None)'))
执行异常（已重试3次）:Traceback (most recent call last):
  File "/opt/hostedtoolcache/Python/3.10.19/x64/lib/python3.10/site-packages/urllib3/connection.py", line 198, in _new_conn
    sock = connection.create_connection(
  File "/opt/hostedtoolcache/Python/3.10.19/x64/lib/python3.10/site-packages/urllib3/util/connection.py", line 85, in create_connection
    raise err
  File "/opt/hostedtoolcache/Python/3.10.19/x64/lib/python3.10/site-packages/urllib3/util/connection.py", line 73, in create_connection
    sock.connect(sa)
TimeoutError: [Errno 110] Connection timed out

The above exception was the direct cause of the following exception:

Traceback (most recent call last):
  File "/opt/hostedtoolcache/Python/3.10.19/x64/lib/python3.10/site-packages/urllib3/connectionpool.py", line 787, in urlopen
    response = self._make_request(
  File "/opt/hostedtoolcache/Python/3.10.19/x64/lib/python3.10/site-packages/urllib3/connectionpool.py", line 488, in _make_request
    raise new_e
  File "/opt/hostedtoolcache/Python/3.10.19/x64/lib/python3.10/site-packages/urllib3/connectionpool.py", line 464, in _make_request
    self._validate_conn(conn)
  File "/opt/hostedtoolcache/Python/3.10.19/x64/lib/python3.10/site-packages/urllib3/connectionpool.py", line 1093, in _validate_conn
    conn.connect()
  File "/opt/hostedtoolcache/Python/3.10.19/x64/lib/python3.10/site-packages/urllib3/connection.py", line 753, in connect
    self.sock = sock = self._new_conn()
  File "/opt/hostedtoolcache/Python/3.10.19/x64/lib/python3.10/site-packages/urllib3/connection.py", line 207, in _new_conn
    raise ConnectTimeoutError(
urllib3.exceptions.ConnectTimeoutError: (<urllib3.connection.HTTPSConnection object at 0x7f11c27dfe20>, 'Connection to api-mifit-cn3.zepp.com timed out. (connect timeout=None)')

The above exception was the direct cause of the following exception:

Traceback (most recent call last):
  File "/opt/hostedtoolcache/Python/3.10.19/x64/lib/python3.10/site-packages/requests/adapters.py", line 644, in send
    resp = conn.urlopen(
  File "/opt/hostedtoolcache/Python/3.10.19/x64/lib/python3.10/site-packages/urllib3/connectionpool.py", line 841, in urlopen
    retries = retries.increment(
  File "/opt/hostedtoolcache/Python/3.10.19/x64/lib/python3.10/site-packages/urllib3/util/retry.py", line 519, in increment
    raise MaxRetryError(_pool, url, reason) from reason  # type: ignore[arg-type]
urllib3.exceptions.MaxRetryError: HTTPSConnectionPool(host='api-mifit-cn3.zepp.com', port=443): Max retries exceeded with url: /huami.health.getUserInfo.json?r=00b7912b-790a-4552-81b1-3742f9dd1e76&userid=1188760659&appid=428135909242707968&channel=Normal&country=CN&cv=50818_6.14.0&device=android_31&device_type=android_phone&lang=zh_CN&timezone=Asia%2FShanghai&v=2.0 (Caused by ConnectTimeoutError(<urllib3.connection.HTTPSConnection object at 0x7f11c27dfe20>, 'Connection to api-mifit-cn3.zepp.com timed out. (connect timeout=None)'))

During handling of the above exception, another exception occurred:

Traceback (most recent call last):
  File "/home/runner/work/mimotion/mimotion/main.py", line 302, in run_single_account
    exec_msg, success = runner.login_and_post_step(min_step, max_step)
  File "/home/runner/work/mimotion/mimotion/main.py", line 260, in login_and_post_step
    app_token = self.login()
  File "/home/runner/work/mimotion/mimotion/main.py", line 202, in login
    ok,msg = zeppHelper.check_app_token(app_token)
  File "/home/runner/work/mimotion/mimotion/util/zepp_helper.py", line 198, in check_app_token
    response = requests.get(url, params=params, headers=headers)
  File "/opt/hostedtoolcache/Python/3.10.19/x64/lib/python3.10/site-packages/requests/api.py", line 73, in get
    return request("get", url, params=params, **kwargs)
  File "/opt/hostedtoolcache/Python/3.10.19/x64/lib/python3.10/site-packages/requests/api.py", line 59, in request
    return session.request(method=method, url=url, **kwargs)
  File "/opt/hostedtoolcache/Python/3.10.19/x64/lib/python3.10/site-packages/requests/sessions.py", line 589, in request
    resp = self.send(prep, **send_kwargs)
  File "/opt/hostedtoolcache/Python/3.10.19/x64/lib/python3.10/site-packages/requests/sessions.py", line 703, in send
    r = adapter.send(request, **kwargs)
  File "/opt/hostedtoolcache/Python/3.10.19/x64/lib/python3.10/site-packages/requests/adapters.py", line 665, in send
    raise ConnectTimeout(e, request=request)
requests.exceptions.ConnectTimeout: HTTPSConnectionPool(host='api-mifit-cn3.zepp.com', port=443): Max retries exceeded with url: /huami.health.getUserInfo.json?r=00b7912b-790a-4552-81b1-3742f9dd1e76&userid=1188760659&appid=428135909242707968&channel=Normal&country=CN&cv=50818_6.14.0&device=android_31&device_type=android_phone&lang=zh_CN&timezone=Asia%2FShanghai&v=2.0 (Caused by ConnectTimeoutError(<urllib3.connection.HTTPSConnection object at 0x7f11c27dfe20>, 'Connection to api-mifit-cn3.zepp.com timed out. (connect timeout=None)'))


2025-10-18 22:24:47,223 - INFO - 开始重试 7 个失败账号
2025-10-18 22:24:47,224 - INFO - 失败账号数量超过阈值，跳过第1轮重试
2025-10-18 22:24:47,224 - INFO - 重试总结：总共 0 个账号重试成功
2025-10-18 22:24:47,226 - INFO - 批次执行完成 - 成功：0，失败：7，耗时：2487.15秒
[2025-10-19 06:18:03]
[7/7]账号：693****.com
第1次尝试失败，2次重试机会: HTTPSConnectionPool(host='api-mifit-cn3.zepp.com', port=443): Max retries exceeded with url: /huami.health.getUserInfo.json?r=00b7912b-790a-4552-81b1-3742f9dd1e76&userid=1188760659&appid=428135909242707968&channel=Normal&country=CN&cv=50818_6.14.0&device=android_31&device_type=android_phone&lang=zh_CN&timezone=Asia%2FShanghai&v=2.0 (Caused by ConnectTimeoutError(<urllib3.connection.HTTPSConnection object at 0x7f11c27dd8a0>, 'Connection to api-mifit-cn3.zepp.com timed out. (connect timeout=None)'))
第2次尝试失败，1次重试机会: HTTPSConnectionPool(host='api-mifit-cn3.zepp.com', port=443): Max retries exceeded with url: /huami.health.getUserInfo.json?r=00b7912b-790a-4552-81b1-3742f9dd1e76&userid=1188760659&appid=428135909242707968&channel=Normal&country=CN&cv=50818_6.14.0&device=android_31&device_type=android_phone&lang=zh_CN&timezone=Asia%2FShanghai&v=2.0 (Caused by ConnectTimeoutError(<urllib3.connection.HTTPSConnection object at 0x7f11c27dd030>, 'Connection to api-mifit-cn3.zepp.com timed out. (connect timeout=None)'))
执行异常（已重试3次）:Traceback (most recent call last):
  File "/opt/hostedtoolcache/Python/3.10.19/x64/lib/python3.10/site-packages/urllib3/connection.py", line 198, in _new_conn
    sock = connection.create_connection(
  File "/opt/hostedtoolcache/Python/3.10.19/x64/lib/python3.10/site-packages/urllib3/util/connection.py", line 85, in create_connection
    raise err
  File "/opt/hostedtoolcache/Python/3.10.19/x64/lib/python3.10/site-packages/urllib3/util/connection.py", line 73, in create_connection
    sock.connect(sa)
TimeoutError: [Errno 110] Connection timed out

The above exception was the direct cause of the following exception:

Traceback (most recent call last):
  File "/opt/hostedtoolcache/Python/3.10.19/x64/lib/python3.10/site-packages/urllib3/connectionpool.py", line 787, in urlopen
    response = self._make_request(
  File "/opt/hostedtoolcache/Python/3.10.19/x64/lib/python3.10/site-packages/urllib3/connectionpool.py", line 488, in _make_request
    raise new_e
  File "/opt/hostedtoolcache/Python/3.10.19/x64/lib/python3.10/site-packages/urllib3/connectionpool.py", line 464, in _make_request
    self._validate_conn(conn)
  File "/opt/hostedtoolcache/Python/3.10.19/x64/lib/python3.10/site-packages/urllib3/connectionpool.py", line 1093, in _validate_conn
    conn.connect()
  File "/opt/hostedtoolcache/Python/3.10.19/x64/lib/python3.10/site-packages/urllib3/connection.py", line 753, in connect
    self.sock = sock = self._new_conn()
  File "/opt/hostedtoolcache/Python/3.10.19/x64/lib/python3.10/site-packages/urllib3/connection.py", line 207, in _new_conn
    raise ConnectTimeoutError(
urllib3.exceptions.ConnectTimeoutError: (<urllib3.connection.HTTPSConnection object at 0x7f11c27dd0f0>, 'Connection to api-mifit-cn3.zepp.com timed out. (connect timeout=None)')

The above exception was the direct cause of the following exception:

Traceback (most recent call last):
  File "/opt/hostedtoolcache/Python/3.10.19/x64/lib/python3.10/site-packages/requests/adapters.py", line 644, in send
    resp = conn.urlopen(
  File "/opt/hostedtoolcache/Python/3.10.19/x64/lib/python3.10/site-packages/urllib3/connectionpool.py", line 841, in urlopen
    retries = retries.increment(
  File "/opt/hostedtoolcache/Python/3.10.19/x64/lib/python3.10/site-packages/urllib3/util/retry.py", line 519, in increment
    raise MaxRetryError(_pool, url, reason) from reason  # type: ignore[arg-type]
urllib3.exceptions.MaxRetryError: HTTPSConnectionPool(host='api-mifit-cn3.zepp.com', port=443): Max retries exceeded with url: /huami.health.getUserInfo.json?r=00b7912b-790a-4552-81b1-3742f9dd1e76&userid=1188760659&appid=428135909242707968&channel=Normal&country=CN&cv=50818_6.14.0&device=android_31&device_type=android_phone&lang=zh_CN&timezone=Asia%2FShanghai&v=2.0 (Caused by ConnectTimeoutError(<urllib3.connection.HTTPSConnection object at 0x7f11c27dd0f0>, 'Connection to api-mifit-cn3.zepp.com timed out. (connect timeout=None)'))

During handling of the above exception, another exception occurred:

Traceback (most recent call last):
  File "/home/runner/work/mimotion/mimotion/main.py", line 302, in run_single_account
    exec_msg, success = runner.login_and_post_step(min_step, max_step)
  File "/home/runner/work/mimotion/mimotion/main.py", line 260, in login_and_post_step
    app_token = self.login()
  File "/home/runner/work/mimotion/mimotion/main.py", line 202, in login
    ok,msg = zeppHelper.check_app_token(app_token)
  File "/home/runner/work/mimotion/mimotion/util/zepp_helper.py", line 198, in check_app_token
    response = requests.get(url, params=params, headers=headers)
  File "/opt/hostedtoolcache/Python/3.10.19/x64/lib/python3.10/site-packages/requests/api.py", line 73, in get
    return request("get", url, params=params, **kwargs)
  File "/opt/hostedtoolcache/Python/3.10.19/x64/lib/python3.10/site-packages/requests/api.py", line 59, in request
    return session.request(method=method, url=url, **kwargs)
  File "/opt/hostedtoolcache/Python/3.10.19/x64/lib/python3.10/site-packages/requests/sessions.py", line 589, in request
    resp = self.send(prep, **send_kwargs)
  File "/opt/hostedtoolcache/Python/3.10.19/x64/lib/python3.10/site-packages/requests/sessions.py", line 703, in send
    r = adapter.send(request, **kwargs)
  File "/opt/hostedtoolcache/Python/3.10.19/x64/lib/python3.10/site-packages/requests/adapters.py", line 665, in send
    raise ConnectTimeout(e, request=request)
requests.exceptions.ConnectTimeout: HTTPSConnectionPool(host='api-mifit-cn3.zepp.com', port=443): Max retries exceeded with url: /huami.health.getUserInfo.json?r=00b7912b-790a-4552-81b1-3742f9dd1e76&userid=1188760659&appid=428135909242707968&channel=Normal&country=CN&cv=50818_6.14.0&device=android_31&device_type=android_phone&lang=zh_CN&timezone=Asia%2FShanghai&v=2.0 (Caused by ConnectTimeoutError(<urllib3.connection.HTTPSConnection object at 0x7f11c27dd0f0>, 'Connection to api-mifit-cn3.zepp.com timed out. (connect timeout=None)'))



检测到 7 个失败账号，开始单独重试...
失败账号数量(7)超过重试阈值(3)，跳过第1轮重试

重试总结：总共 0 个账号重试成功

执行账号总数7，成功：0，失败：7，耗时：2487.15秒
本批次执行完毕，已更新批次号至 9，下次将从此批次开始。
